<?xml version="1.0" ?>
<robot name="lite3">
  <link name="base">
    <visual>
      <origin rpy="0 0 0" xyz="0 0 0"/>
      <geometry>
        <box size="0.001 0.001 0.001"/>
      </geometry>
    </visual>
  </link>
  <joint name="floating_base" type="fixed">
    <origin rpy="0 0 0" xyz="0 0 0"/>
    <parent link="base"/>
    <child link="trunk"/>
  </joint>
  <link name="trunk">
    <visual>
      <origin rpy="0 0 1.5708" xyz="-0.05 -0.5 0.08"/>
      <geometry>
        <mesh filename="../meshes/trunk.dae" scale="1 1 1"/>
      </geometry>
    </visual>
    <collision>
      <geometry>
        <box size="0.234 0.184 0.08"/>
      </geometry>
    </collision>
    <inertial>
      <origin xyz="0.004098 -0.000663 -0.002069"/>
      <mass value="4.130"/>
      <inertia ixx="0.016982120" ixy="2.1294E-05" ixz="6.0763E-05" iyy="0.030466501" iyz="1.7968E-05" izz="0.042609956"/>
    </inertial>
  </link>
  <joint name="imu_joint" type="fixed">
    <parent link="trunk"/>
    <child link="imu_link"/>
    <origin rpy="0 0 0" xyz="0 0 0"/>
  </joint>
  <link name="imu_link">
    <inertial>
      <mass value="0.001"/>
      <origin rpy="0 0 0" xyz="0 0 0"/>
      <inertia ixx="0.0001" ixy="0" ixz="0" iyy="0.0001" iyz="0" izz="0.0001"/>
    </inertial>
    <visual>
      <origin rpy="0 0 0" xyz="0 0 0"/>
      <geometry>
        <box size="0.001 0.001 0.001"/>
      </geometry>
    </visual>
    <collision>
      <origin rpy="0 0 0" xyz="0 0 0"/>
      <geometry>
        <box size=".001 .001 .001"/>
      </geometry>
    </collision>
  </link>
  <joint name="FR_hip_joint" type="revolute">
    <origin xyz="0.1745 -0.062 0"/>
    <parent link="trunk"/>
    <child link="FR_hip"/>
    <axis xyz="1 0 0"/>
    <limit effort="40" lower="-6.28" upper="6.28" velocity="30"/>
  </joint>
  <link name="FR_hip">
    <inertial>
      <origin xyz="-0.0047 0.0091 -0.0018"/>
      <mass value="0.428"/>
      <inertia ixx="0.00014538" ixy="-8.1551E-07" ixz="-1.2639E-05" iyy="0.00024024" iyz="-1.3441E-06" izz="0.00013038"/>
    </inertial>
    <visual>
      <origin rpy="0 0 1.5708" xyz="-0.231 -0.44 0.09"/>
      <geometry>
        <mesh filename="../meshes/FR_hip.dae" scale="1 1 1"/>
      </geometry>
    </visual>
    <collision>
      <origin rpy="1.57079632679 0 0" xyz="0 0 0"/>
      <geometry>
        <cylinder length="0.04" radius="0.046"/>
      </geometry>
    </collision>
  </link>
  <joint name="FR_hip_fixed" type="fixed">
    <origin rpy="0 0 0" xyz="0 -0.08 0"/>
    <parent link="FR_hip"/>
    <child link="FR_thigh_shoulder"/>
  </joint>
  <!-- this link is only for collision -->
  <link name="FR_thigh_shoulder">
    <collision>
      <origin rpy="1.57079632679 0 0" xyz="0 0 0"/>
      <geometry>
        <cylinder length="0.032" radius="0.041"/>
      </geometry>
    </collision>
  </link>
  <joint name="FR_thigh_joint" type="revolute">
    <origin xyz="0 -0.0985 0"/>
    <parent link="FR_hip"/>
    <child link="FR_thigh"/>
    <axis xyz="0 1 0"/>
    <limit effort="40" lower="-6.28" upper="6.28" velocity="30"/>
  </joint>
  <link name="FR_thigh">
    <inertial>
      <origin xyz="-0.00523 0.0216 -0.0273"/>
      <mass value="0.61"/>
      <inertia ixx="0.001" ixy="2.5E-06" ixz="-1.12E-04" iyy="0.00116" iyz="-3.75E-07" izz="2.68E-04"/>
    </inertial>
    <visual>
      <origin rpy="-3.5708 0 1.5708" xyz="0.27 -0.335 0.02"/>
      <geometry>
        <mesh filename="../meshes/R_thigh.dae" scale="1 1 1"/>
      </geometry>
    </visual>
    <collision>
      <origin xyz="0 0.01 -0.11"/>
      <geometry>
        <box size="0.035 0.02 0.20"/>
      </geometry>
    </collision>
  </link>
  <joint name="FR_calf_joint" type="revolute">
    <origin xyz="0 0 -0.20"/>
    <parent link="FR_thigh"/>
    <child link="FR_calf"/>
    <axis xyz="0 1 0"/>
    <limit effort="65" lower="-6.28" upper="6.28" velocity="20"/>
  </joint>
  <link name="FR_calf">
    <inertial>
      <origin xyz="0.00585 -8.732E-07 -0.12"/>
      <mass value="0.115"/>
      <inertia ixx="6.68E-04" ixy="-1.24E-08" ixz="6.91E-06" iyy="6.86E-04" iyz="5.65E-09" izz="3.155E-05"/>
    </inertial>
    <visual>
      <origin rpy="-1.57079632679 0 0" xyz="0.005 0.01 -0.03"/>
      <geometry>
        <mesh filename="../meshes/calf.dae" scale="1 1 1"/>
      </geometry>
    </visual>
    <collision>
      <origin xyz="0 0.01 -0.11"/>
      <geometry>
        <box size="0.02 0.02 0.22"/>
      </geometry>
    </collision>
  </link>
  <joint name="FR_foot_fixed" type="fixed" dont_collapse="true">
    <origin xyz="0 0 -0.20"/>
    <parent link="FR_calf"/>
    <child link="FR_foot"/>
  </joint>
  <link name="FR_foot">
    <inertial>
      <mass value="0.06"/>
      <inertia ixx="1E-12" ixy="0" ixz="0" iyy="1E-12" iyz="0" izz="1E-12"/>
    </inertial>
    <collision>
      <geometry>
        <sphere radius="0.04"/>
      </geometry>
    </collision>
  </link>
  <joint name="FL_hip_joint" type="revolute">
    <origin xyz="0.1745 0.062 0"/>
    <parent link="trunk"/>
    <child link="FL_hip"/>
    <axis xyz="1 0 0"/>
    <limit effort="40" lower="-6.28" upper="6.28" velocity="30"/>
  </joint>
  <link name="FL_hip">
    <inertial>
      <origin xyz="-0.0047 -0.0091 -0.0018"/>
      <mass value="0.428"/>
      <inertia ixx="0.00014538" ixy="8.1579E-07" ixz="-1.264E-05" iyy="0.00024024" iyz="1.3443E-06" izz="0.00013038"/>
    </inertial>
    <visual>
      <origin rpy="0 0 1.5708" xyz="-0.231 -0.56 0.09"/>
      <geometry>
        <mesh filename="../meshes/FL_hip.dae" scale="1 1 1"/>
      </geometry>
    </visual>
    <collision>
      <origin rpy="1.57079632679 0 0" xyz="0 0 0"/>
      <geometry>
        <cylinder length="0.04" radius="0.046"/>
      </geometry>
    </collision>
  </link>
  <joint name="FL_hip_fixed" type="fixed">
    <origin rpy="0 0 0" xyz="0 0.08 0"/>
    <parent link="FL_hip"/>
    <child link="FL_thigh_shoulder"/>
  </joint>
  <!-- this link is only for collision -->
  <link name="FL_thigh_shoulder">
    <collision>
      <origin rpy="1.57079632679 0 0" xyz="0 0 0"/>
      <geometry>
        <cylinder length="0.032" radius="0.041"/>
      </geometry>
    </collision>
  </link>
  <joint name="FL_thigh_joint" type="revolute">
    <origin xyz="0 0.0985 0"/>
    <parent link="FL_hip"/>
    <child link="FL_thigh"/>
    <axis xyz="0 1 0"/>
    <limit effort="40" lower="-6.28" upper="6.28" velocity="30"/>
  </joint>
  <link name="FL_thigh">
    <inertial>
      <origin xyz="-0.00523 -0.0216 -0.0273"/>
      <mass value="0.61"/>
      <inertia ixx="0.001" ixy="-2.5E-06" ixz="-1.12E-04" iyy="0.00116" iyz="3.75E-07" izz="2.68E-04"/>
    </inertial>
    <visual>
      <origin rpy="-3.5708 0 1.5708" xyz="0.27 -0.67 0.02"/>
      <geometry>
        <mesh filename="../meshes/L_thigh.dae" scale="1 1 1"/>
      </geometry>
    </visual>
    <collision>
      <origin xyz="0 -0.01 -0.11"/>
      <geometry>
        <box size="0.035 0.02 0.20"/>
      </geometry>
    </collision>
  </link>
  <joint name="FL_calf_joint" type="revolute">
    <origin xyz="0 0 -0.20"/>
    <parent link="FL_thigh"/>
    <child link="FL_calf"/>
    <axis xyz="0 1 0"/>
    <limit effort="65" lower="-6.28" upper="6.28" velocity="20"/>
  </joint>
  <link name="FL_calf">
    <inertial>
      <origin xyz="0.00585 -8.732E-07 -0.12"/>
      <mass value="0.115"/>
      <inertia ixx="6.68E-04" ixy="-1.24E-08" ixz="6.91E-06" iyy="6.86E-04" iyz="5.65E-09" izz="3.155E-05"/>
    </inertial>
    <visual>
      <origin rpy="-1.57079632679 0 0" xyz="0.005 -0.015 -0.03"/>
      <geometry>
        <mesh filename="../meshes/calf.dae" scale="1 1 1"/>
      </geometry>
    </visual>
    <collision>
      <origin xyz="0 -0.01 -0.11"/>
      <geometry>
        <box size="0.02 0.02 0.22"/>
      </geometry>
    </collision>
  </link>
  <joint name="FL_foot_fixed" type="fixed" dont_collapse="true">
    <origin xyz="0 0 -0.20"/>
    <parent link="FL_calf"/>
    <child link="FL_foot"/>
  </joint>
  <link name="FL_foot">
    <inertial>
      <mass value="0.06"/>
      <inertia ixx="1E-12" ixy="0" ixz="0" iyy="1E-12" iyz="0" izz="1E-12"/>
    </inertial>
    <collision>
      <geometry>
        <sphere radius="0.04"/>
      </geometry>
    </collision>
  </link>
  <joint name="RR_hip_joint" type="revolute">
    <origin xyz="-0.1745 -0.062 0"/>
    <parent link="trunk"/>
    <child link="RR_hip"/>
    <axis xyz="1 0 0"/>
    <limit effort="40" lower="-6.28" upper="6.28" velocity="30"/>
  </joint>
  <link name="RR_hip">
    <inertial>
      <origin xyz="0.0047 0.0091 -0.0018"/>
      <mass value="0.428"/>
      <inertia ixx="0.00014538" ixy="8.1545E-07" ixz="1.2639E-05" iyy="0.00024024" iyz="-1.344E-06" izz="0.00013038"/>
    </inertial>
    <visual>
      <origin rpy="0 0 1.5708" xyz="0.12 -0.44 0.09"/>
      <geometry>
        <mesh filename="../meshes/RR_hip.dae" scale="1 1 1"/>
      </geometry>
    </visual>
    <collision>
      <origin rpy="1.57079632679 0 0" xyz="0 0 0"/>
      <geometry>
        <cylinder length="0.04" radius="0.046"/>
      </geometry>
    </collision>
  </link>
  <joint name="RR_hip_fixed" type="fixed">
    <origin rpy="0 0 0" xyz="0 -0.08 0"/>
    <parent link="RR_hip"/>
    <child link="RR_thigh_shoulder"/>
  </joint>
  <!-- this link is only for collision -->
  <link name="RR_thigh_shoulder">
    <collision>
      <origin rpy="1.57079632679 0 0" xyz="0 0 0"/>
      <geometry>
        <cylinder length="0.032" radius="0.041"/>
      </geometry>
    </collision>
  </link>
  <joint name="RR_thigh_joint" type="revolute">
    <origin xyz="0 -0.0985 0"/>
    <parent link="RR_hip"/>
    <child link="RR_thigh"/>
    <axis xyz="0 1 0"/>
    <limit effort="40" lower="-6.28" upper="6.28" velocity="30"/>
  </joint>
  <link name="RR_thigh">
    <inertial>
      <origin xyz="-0.00523 0.0216 -0.0273"/>
      <mass value="0.61"/>
      <inertia ixx="0.001" ixy="2.5E-06" ixz="-1.12E-04" iyy="0.00116" iyz="-3.75E-07" izz="2.68E-04"/>
    </inertial>
    <visual>
      <origin rpy="-3.5708 0 1.5708" xyz="0.27 -0.335 0.02"/>
      <geometry>
        <mesh filename="../meshes/R_thigh.dae" scale="1 1 1"/>
      </geometry>
    </visual>
    <collision>
      <origin xyz="0 0.01 -0.11"/>
      <geometry>
        <box size="0.035 0.02 0.20"/>
      </geometry>
    </collision>
  </link>
  <joint name="RR_calf_joint" type="revolute">
    <origin xyz="0 0 -0.20"/>
    <parent link="RR_thigh"/>
    <child link="RR_calf"/>
    <axis xyz="0 1 0"/>
    <limit effort="65" lower="-6.28" upper="6.28" velocity="20"/>
  </joint>
  <link name="RR_calf">
    <inertial>
      <origin xyz="0.00585 -8.732E-07 -0.12"/>
      <mass value="0.115"/>
      <inertia ixx="6.68E-04" ixy="-1.24E-08" ixz="6.91E-06" iyy="6.86E-04" iyz="5.65E-09" izz="3.155E-05"/>
    </inertial>
    <visual>
      <origin rpy="-1.57079632679 0 0" xyz="0.005 0.01 -0.03"/>
      <geometry>
        <mesh filename="../meshes/calf.dae" scale="1 1 1"/>
      </geometry>
    </visual>
    <collision>
      <origin xyz="0 0.01 -0.11"/>
      <geometry>
        <box size="0.02 0.02 0.22"/>
      </geometry>
    </collision>
  </link>
  <joint name="RR_foot_fixed" type="fixed" dont_collapse="true">
    <origin xyz="0 0 -0.20"/>
    <parent link="RR_calf"/>
    <child link="RR_foot"/>
  </joint>
  <link name="RR_foot">
    <inertial>
      <mass value="0.06"/>
      <inertia ixx="1E-12" ixy="0" ixz="0" iyy="1E-12" iyz="0" izz="1E-12"/>
    </inertial>
    <collision>
      <geometry>
        <sphere radius="0.04"/>
      </geometry>
    </collision>
  </link>
  <joint name="RL_hip_joint" type="revolute">
    <origin xyz="-0.1745 0.062 0"/>
    <parent link="trunk"/>
    <child link="RL_hip"/>
    <axis xyz="1 0 0"/>
    <limit effort="40" lower="-6.28" upper="6.28" velocity="30"/>
  </joint>
  <link name="RL_hip">
    <inertial>
      <origin xyz="0.0047 -0.0091 -0.0018"/>
      <mass value="0.428"/>
      <inertia ixx="0.00014538" ixy="-8.1585E-07" ixz="1.2639E-05" iyy="0.00024024" iyz="1.3444E-06" izz="0.00013038"/>
    </inertial>
    <visual>
      <origin rpy="0 0 1.5708" xyz="0.12 -0.56 0.09"/>
      <geometry>
        <mesh filename="../meshes/RL_hip.dae" scale="1 1 1"/>
      </geometry>
    </visual>
    <collision>
      <origin rpy="1.57079632679 0 0" xyz="0 0 0"/>
      <geometry>
        <cylinder length="0.04" radius="0.046"/>
      </geometry>
    </collision>
  </link>
  <joint name="RL_hip_fixed" type="fixed">
    <origin rpy="0 0 0" xyz="0 0.08 0"/>
    <parent link="RL_hip"/>
    <child link="RL_thigh_shoulder"/>
  </joint>
  <!-- this link is only for collision -->
  <link name="RL_thigh_shoulder">
    <collision>
      <origin rpy="1.57079632679 0 0" xyz="0 0 0"/>
      <geometry>
        <cylinder length="0.032" radius="0.041"/>
      </geometry>
    </collision>
  </link>
  <joint name="RL_thigh_joint" type="revolute">
    <origin xyz="0 0.0985 0"/>
    <parent link="RL_hip"/>
    <child link="RL_thigh"/>
    <axis xyz="0 1 0"/>
    <limit effort="40" lower="-6.28" upper="6.28" velocity="30"/>
  </joint>
  <link name="RL_thigh">
    <inertial>
      <origin xyz="-0.00523 -0.0216 -0.0273"/>
      <mass value="0.61"/>
      <inertia ixx="0.001" ixy="-2.5E-06" ixz="-1.12E-04" iyy="0.00116" iyz="3.75E-07" izz="2.68E-04"/>
    </inertial>
    <visual>
      <origin rpy="-3.5708 0 1.5708" xyz="0.27 -0.67 0.02"/>
      <geometry>
        <mesh filename="../meshes/L_thigh.dae" scale="1 1 1"/>
      </geometry>
    </visual>
    <collision>
      <origin xyz="0 -0.01 -0.11"/>
      <geometry>
        <box size="0.035 0.02 0.20"/>
      </geometry>
    </collision>
  </link>
  <joint name="RL_calf_joint" type="revolute">
    <origin xyz="0 0 -0.20"/>
    <parent link="RL_thigh"/>
    <child link="RL_calf"/>
    <axis xyz="0 1 0"/>
    <limit effort="65" lower="-6.28" upper="6.28" velocity="20"/>
  </joint>
  <link name="RL_calf">
    <inertial>
      <origin xyz="0.00585 -8.732E-07 -0.12"/>
      <mass value="0.115"/>
      <inertia ixx="6.68E-04" ixy="-1.24E-08" ixz="6.91E-06" iyy="6.86E-04" iyz="5.65E-09" izz="3.155E-05"/>
    </inertial>
    <visual>
      <origin rpy="-1.57079632679 0 0" xyz="0.005 -0.015 -0.03"/>
      <geometry>
        <mesh filename="../meshes/calf.dae" scale="1 1 1"/>
      </geometry>
    </visual>
    <collision>
      <origin xyz="0 -0.01 -0.11"/>
      <geometry>
        <box size="0.02 0.02 0.22"/>
      </geometry>
    </collision>
  </link>
  <joint name="RL_foot_fixed" type="fixed" dont_collapse="true">
    <origin xyz="0 0 -0.20"/>
    <parent link="RL_calf"/>
    <child link="RL_foot"/>
  </joint>
  <link name="RL_foot">
    <inertial>
      <mass value="0.06"/>
      <inertia ixx="1E-12" ixy="0" ixz="0" iyy="1E-12" iyz="0" izz="1E-12"/>
    </inertial>
    <collision>
      <geometry>
        <sphere radius="0.04"/>
      </geometry>
    </collision>
  </link>

</robot>