<?xml version="1.0" encoding="utf-8"?>
<!-- =================================================================================== -->
<!--   Copyright 2019 ANYbotics, https://www.anybotics.com                               -->
<!-- =================================================================================== -->
<!-- This file contains the description of the ANYmal B robot. -->
<robot name="anymal"
    xmlns:xacro="http://www.ros.org/wiki/xacro">  
    <!-- Material for the visual primitives -->  
    <material name="anymal_material">    
        <color rgba="0.7 0.7 0.7 1.0"/>  
    </material>  
    <!-- Base link -->  
    <link name="base">    
        <visual>      
            <origin rpy="0 0 0" xyz="0 0 0"/>      
            <geometry>        
                <mesh filename="../meshes/anymal_base.dae" scale="0.001 0.001 0.001"/>      
            </geometry>      
            <!-- <material name="anymal_material"/>     -->
        </visual>    
        <collision>      
            <!-- Main Body -->      
            <origin rpy="0 0 0" xyz="0 0 0.08"/>      
            <geometry>        
                <box size="0.531 0.27 0.24"/>      
            </geometry>    
        </collision>    
        <inertial>      
            <origin rpy="0 0 0" xyz="-0.001960558279 -0.001413217745 0.050207125344"/>      
            <mass value="16.793507758"/>      
            <inertia ixx="0.217391101503" ixy="-0.00132873239126" ixz="-0.00228200226173" iyy="0.639432546734" iyz="-0.00138078263145" izz="0.62414077654"/>    
        </inertial>  
    </link>  
    <link name="FL_hip">
        <visual>      
            <origin rpy="0 0 0.0" xyz="0 0 0"/>      
            <geometry>        
                <mesh filename="../meshes/anymal_hip_l.dae" scale="0.001 0.001     0.001"/>      
            </geometry>      
            <!-- <material name="anymal_material"/>     -->
        </visual> 
        <inertial>      
            <origin rpy="0 0 0" xyz="0.064516258147 -0.003787101702 -0.000152184388"/>      
            <mass value="1.42462064"/>      
            <inertia ixx="0.00243023349564" ixy="-1.53023971e-05" ixz="-2.1819095354e-05" iyy="0.00230257239103" iyz="2.6473021273e-05" izz="0.0019806759227"/>    
        </inertial>  
    </link>  
    <!-- Hip joint -->  
    <joint name="FL_hip_joint" type="revolute">
        <parent link="base"/>    
        <child link="FL_hip"/>
        <origin xyz="0.277 0.116 0.0"/>    
        <axis xyz="1 0 0"/>    
        <limit command_effort="80" current="10" effort="80" gear_velocity="10" lower="-9.42" upper="9.42" velocity="15"/>    
        <dynamics damping="0.0" friction="0.0"/>  
    </joint>  
    <link name="FL_thigh">
        <visual>      
            <origin rpy="0 0 0.0" xyz="0 0 0"/>      
            <geometry>        
                <mesh filename="../meshes/anymal_thigh_l.dae" scale="0.001 0.001     0.001"/>      
            </geometry>      
            <!-- <material name="anymal_material"/>     -->
        </visual>        
        <collision>      
            <!-- KFE actuator -->      
            <origin rpy="1.57079632679 0 0" xyz="0.0 0.069 -0.25"/>      
            <geometry>        
                <cylinder length="0.12" radius="0.06"/>      
            </geometry>    
        </collision>    
        <inertial>      
            <origin rpy="0 0 0" xyz="-0.003897968082 0.054226618537 -0.214583373795"/>      
            <mass value="1.634976467"/>      
            <inertia ixx="0.0120367944369" ixy="6.762065206e-05" ixz="0.000287806340448" iyy="0.0120643637939" iyz="-0.00140610131218" izz="0.00249422574881"/>    
        </inertial>  
    </link>  
    <!-- Thigh joint -->  
    <joint name="FL_thigh_joint" type="revolute">
        <parent link="FL_hip"/>
        <child link="FL_thigh"/>
        <origin xyz="0.0635                    0.041                    0.0"/>    
        <axis xyz="0 1 0"/>
        <limit command_effort="80" effort="80" lower="-9.42" upper="9.42" velocity="20"/>
        <dynamics damping="0.0" friction="0.0"/>
    </joint>
    <link name="FL_calf">
        <visual>
            <origin rpy="0 0 0.0" xyz="0 0 0"/>
            <geometry>
                <mesh filename="../meshes/anymal_shank_l.dae" scale="0.001 0.001     0.001"/>
            </geometry>
            <!-- <material name="anymal_material"/>     -->
        </visual>
        <inertial>
            <origin rpy="0 0 0" xyz="0.030816858139 -0.004617229294 0.000893125713"/>
            <mass value="0.207204302"/>
            <inertia ixx="0.0002104880248" ixy="-5.6750980345e-05" ixz="1.0127699391e-05" iyy="0.000676270210023" iyz="-8.22869024e-07" izz="0.000545032674924"/>
        </inertial>
    </link>
    <!-- Shank joint -->
    <joint name="FL_calf_joint" type="revolute">
        <parent link="FL_thigh"/>
        <child link="FL_calf"/>
        <origin xyz="0.0 0.109 -0.25"/>
        <axis xyz="0 1 0"/>
        <limit command_effort="80" effort="80" lower="-9.42" upper="9.42" velocity="20"/>
        <dynamics damping="0.0" friction="0.0"/>
    </joint>
    <!-- Shank to Adapter joint -->
    <joint name="FL_calf_TO_ADAPTER" type="fixed">
        <parent link="FL_calf"/>
        <child link="LF_ADAPTER"/>
        <origin rpy="0.0 0.0 0.0" xyz="0.1 -0.02 0.0"/>
    </joint>
    <!-- Adapter link -->
    <link name="LF_ADAPTER">
        <visual>
            <origin rpy="0 0 0.0" xyz="0 0 0.032"/>
            <geometry>
                <mesh filename="../meshes/anymal_foot.dae" scale="0.001 0.001     0.001"/>
            </geometry>
            <!-- <material name="anymal_material"/>     -->
        </visual>
        <collision>
            <origin rpy="0 0 0" xyz="0 0 -0.160625"/>
            <geometry>
                <cylinder length="0.25" radius="0.015"/>
            </geometry>
            <!-- <material name="anymal_material"/>     -->
        </collision>
        <inertial>
            <origin rpy="0 0 0" xyz="-8.66e-10 -1.472e-09 -0.244345749188"/>
            <mass value="0.140170767"/>
            <inertia ixx="0.00159938741862" ixy="-9.32e-13" ixz="1.039e-11" iyy="0.00159938741932" iyz="1.7563e-11" izz="5.4423177329e-05"/>
        </inertial>
    </link>
    <!-- Adapter to Foot joint -->
    <joint name="LF_ADAPTER_TO_FOOT" type="fixed" dont_collapse="true">
        <parent link="LF_ADAPTER"/>
        <child link="FL_foot"/>
        <origin rpy="0.0 0.0 0.0" xyz="0.0 0.0 -0.32125"/>
    </joint>
    <!-- Foot link -->
    <link name="FL_foot">
        <collision>
            <origin xyz="0 0 0.02325"/>
            <geometry>
                <sphere radius="0.031"/>
            </geometry>
        </collision>
        <inertial>
            <origin rpy="0 0 0" xyz="0 0 0.02325"/>
            <mass value="0.05"/>
            <inertia ixx="0.001" ixy="-2.63048e-07" ixz="6.815581e-06" iyy="0.001" iyz="-6.815583e-06" izz="8.319196e-06"/>
        </inertial>
    </link>
    <link name="FR_hip">
        <visual>
            <origin rpy="0 0 0.0" xyz="0 0 0"/>
            <geometry>
                <mesh filename="../meshes/anymal_hip_r.dae" scale="0.001 0.001     0.001"/>
            </geometry>
            <!-- <material name="anymal_material"/>     -->
        </visual>
        <inertial>
            <origin rpy="0 0 0" xyz="0.064516258147 0.003787101702 -0.000152184388"/>
            <mass value="1.42462064"/>
            <inertia ixx="0.00243023349564" ixy="1.53023971e-05" ixz="-2.1819095354e-05" iyy="0.00230257239103" iyz="-2.6473021273e-05" izz="0.0019806759227"/>
        </inertial>
    </link>
    <!-- Hip joint -->
    <joint name="FR_hip_joint" type="revolute">
        <parent link="base"/>
        <child link="FR_hip"/>
        <origin xyz="0.277 -0.116 0.0"/>
        <axis xyz="1 0 0"/>
        <limit command_effort="80" effort="80" lower="-9.42" upper="9.42" velocity="15"/>
        <dynamics damping="0.0" friction="0.0"/>
    </joint>
    <link name="FR_thigh">
        <visual>
            <origin rpy="0 0 0.0" xyz="0 0 0"/>
            <geometry>
                <mesh filename="../meshes/anymal_thigh_r.dae" scale="0.001 0.001     0.001"/>
            </geometry>
            <!-- <material name="anymal_material"/>     -->
        </visual>
        <collision>
            <!-- KFE actuator -->
            <origin rpy="1.57079632679 0 0" xyz="0.0 -0.069 -0.25"/>
            <geometry>
                <cylinder length="0.12" radius="0.06"/>
            </geometry>
        </collision>
        <inertial>
            <origin rpy="0 0 0" xyz="-0.003897968082 -0.054226618537 -0.214583373795"/>
            <mass value="1.634976467"/>
            <inertia ixx="0.0120367944369" ixy="-6.762065206e-05" ixz="0.000287806340448" iyy="0.0120643637939" iyz="0.00140610131218" izz="0.00249422574881"/>
        </inertial>
    </link>
    <!-- Thigh joint -->
    <joint name="FR_thigh_joint" type="revolute">
        <parent link="FR_hip"/>
        <child link="FR_thigh"/>
        <origin xyz="0.0635                    -0.041                    0.0"/>
        <axis xyz="0 1 0"/>
        <limit command_effort="80" effort="80" lower="-9.42" upper="9.42" velocity="20"/>
        <dynamics damping="0.0" friction="0.0"/>
    </joint>
    <link name="FR_calf">
        <visual>
            <origin rpy="0 0 0.0" xyz="0 0 0"/>
            <geometry>
                <mesh filename="../meshes/anymal_shank_r.dae" scale="0.001 0.001     0.001"/>
            </geometry>
            <!-- <material name="anymal_material"/>     -->
        </visual>
        <inertial>
            <origin rpy="0 0 0" xyz="0.030816858139 0.004617229294 0.000893125713"/>
            <mass value="0.207204302"/>
            <inertia ixx="0.0002104880248" ixy="5.6750980345e-05" ixz="1.0127699391e-05" iyy="0.000676270210023" iyz="8.22869024e-07" izz="0.000545032674924"/>
        </inertial>
    </link>
    <!-- Shank joint -->
    <joint name="FR_calf_joint" type="revolute">
        <parent link="FR_thigh"/>
        <child link="FR_calf"/>
        <origin xyz="0.0 -0.109 -0.25"/>
        <axis xyz="0 1 0"/>
        <limit command_effort="80" effort="80" lower="-9.42" upper="9.42" velocity="20"/>
        <dynamics damping="0.0" friction="0.0"/>
    </joint>
    <!-- Shank to Adapter joint -->
    <joint name="FR_calf_TO_ADAPTER" type="fixed">
        <parent link="FR_calf"/>
        <child link="RF_ADAPTER"/>
        <origin rpy="-0.0 0.0 -0.0" xyz="0.1 0.02 0.0"/>
    </joint>
    <!-- Adapter link -->
    <link name="RF_ADAPTER">
        <visual>
            <origin rpy="0 0 0.0" xyz="0 0 0.032"/>
            <geometry>
                <mesh filename="../meshes/anymal_foot.dae" scale="0.001 0.001     0.001"/>
            </geometry>
            <!-- <material name="anymal_material"/>     -->
        </visual>
        <collision>
            <origin rpy="0 0 0" xyz="0 0 -0.160625"/>
            <geometry>
                <cylinder length="0.25" radius="0.015"/>
            </geometry>
            <!-- <material name="anymal_material"/>     -->
        </collision>
        <inertial>
            <origin rpy="0 0 0" xyz="-8.66e-10 -1.472e-09 -0.244345749188"/>
            <mass value="0.140170767"/>
            <inertia ixx="0.00159938741862" ixy="-9.32e-13" ixz="1.039e-11" iyy="0.00159938741932" iyz="1.7563e-11" izz="5.4423177329e-05"/>
        </inertial>
    </link>
    <!-- Adapter to Foot joint -->
    <joint name="RF_ADAPTER_TO_FOOT" type="fixed" dont_collapse="true">
        <parent link="RF_ADAPTER"/>
        <child link="FR_foot"/>
        <origin rpy="-0.0 0.0 -0.0" xyz="0.0 -0.0 -0.32125"/>
    </joint>
    <!-- Foot link -->
    <link name="FR_foot">
        <collision>
            <origin xyz="0 0 0.02325"/>
            <geometry>
                <sphere radius="0.031"/>
            </geometry>
        </collision>
        <inertial>
            <origin rpy="0 0 0" xyz="0 0 0.02325"/>
            <mass value="0.05"/>
            <inertia ixx="0.001" ixy="-2.63048e-07" ixz="6.815581e-06" iyy="0.001" iyz="-6.815583e-06" izz="8.319196e-06"/>
        </inertial>
    </link>
    <link name="RL_hip">
        <visual>
            <origin rpy="0 0 -3.14159265359" xyz="0 0 0"/>
            <geometry>
                <mesh filename="../meshes/anymal_hip_r.dae" scale="0.001 0.001     0.001"/>
            </geometry>
            <!-- <material name="anymal_material"/>     -->
        </visual>
        <inertial>
            <origin rpy="0 0 0" xyz="-0.064516258147 -0.003787101702 -0.000152184388"/>
            <mass value="1.42462064"/>
            <inertia ixx="0.00243023349564" ixy="1.53023971e-05" ixz="2.1819095354e-05" iyy="0.00230257239103" iyz="2.6473021273e-05" izz="0.0019806759227"/>
        </inertial>
    </link>
    <!-- Hip joint -->
    <joint name="RL_hip_joint" type="revolute">
        <parent link="base"/>
        <child link="RL_hip"/>
        <origin xyz="-0.277 0.116 0.0"/>
        <axis xyz="1 0 0"/>
        <limit command_effort="80" current="10" effort="80" gear_velocity="10" lower="-9.42" upper="9.42" velocity="15"/>
        <dynamics damping="0.0" friction="0.0"/>
    </joint>
    <link name="RL_thigh">
        <visual>
            <origin rpy="0 0 -3.14159265359" xyz="0 0 0"/>
            <geometry>
                <mesh filename="../meshes/anymal_thigh_r.dae" scale="0.001 0.001     0.001"/>
            </geometry>
            <!-- <material name="anymal_material"/>     -->
        </visual>
        <collision>
            <!-- KFE actuator -->
            <origin rpy="1.57079632679 0 0" xyz="0.0 0.069 -0.25"/>
            <geometry>
                <cylinder length="0.12" radius="0.06"/>
            </geometry>
        </collision>
        <inertial>
            <origin rpy="0 0 0" xyz="0.003897968082 0.054226618537 -0.214583373795"/>
            <mass value="1.634976467"/>
            <inertia ixx="0.0120367944369" ixy="-6.762065206e-05" ixz="-0.000287806340448" iyy="0.0120643637939" iyz="-0.00140610131218" izz="0.00249422574881"/>
        </inertial>
    </link>
    <!-- Thigh joint -->
    <joint name="RL_thigh_joint" type="revolute">
        <parent link="RL_hip"/>
        <child link="RL_thigh"/>
        <origin xyz="-0.0635                    0.041                    0.0"/>
        <axis xyz="0 1 0"/>
        <limit command_effort="80" effort="80" lower="-9.42" upper="9.42" velocity="20"/>
        <dynamics damping="0.0" friction="0.0"/>
    </joint>
    <link name="RL_calf">
        <visual>
            <origin rpy="0 0 -3.14159265359" xyz="0 0 0"/>
            <geometry>
                <mesh filename="../meshes/anymal_shank_r.dae" scale="0.001 0.001     0.001"/>
            </geometry>
            <!-- <material name="anymal_material"/>     -->
        </visual>
        <inertial>
            <origin rpy="0 0 0" xyz="-0.030816858139 -0.004617229294 0.000893125713"/>
            <mass value="0.207204302"/>
            <inertia ixx="0.0002104880248" ixy="5.6750980345e-05" ixz="-1.0127699391e-05" iyy="0.000676270210023" iyz="-8.22869024e-07" izz="0.000545032674924"/>
        </inertial>
    </link>
    <!-- Shank joint -->
    <joint name="RL_calf_joint" type="revolute">
        <parent link="RL_thigh"/>
        <child link="RL_calf"/>
        <origin xyz="-0.0 0.109 -0.25"/>
        <axis xyz="0 1 0"/>
        <limit command_effort="80" effort="80" lower="-9.42" upper="9.42" velocity="20"/>
        <dynamics damping="0.0" friction="0.0"/>
    </joint>
    <!-- Shank to Adapter joint -->
    <joint name="RL_calf_TO_ADAPTER" type="fixed">
        <parent link="RL_calf"/>
        <child link="LH_ADAPTER"/>
        <origin rpy="0.0 -0.0 -0.0" xyz="-0.1 -0.02 0.0"/>
    </joint>
    <!-- Adapter link -->
    <link name="LH_ADAPTER">
        <visual>
            <origin rpy="0 0 -3.14159265359" xyz="0 0 0.032"/>
            <geometry>
                <mesh filename="../meshes/anymal_foot.dae" scale="0.001 0.001     0.001"/>
            </geometry>
            <!-- <material name="anymal_material"/>     -->
        </visual>
        <collision>
            <origin rpy="0 0 0" xyz="0 0 -0.160625"/>
            <geometry>
                <cylinder length="0.25" radius="0.015"/>
            </geometry>
            <!-- <material name="anymal_material"/>     -->
        </collision>
        <inertial>
            <origin rpy="0 0 0" xyz="-8.66e-10 -1.472e-09 -0.244345749188"/>
            <mass value="0.140170767"/>
            <inertia ixx="0.00159938741862" ixy="-9.32e-13" ixz="1.039e-11" iyy="0.00159938741932" iyz="1.7563e-11" izz="5.4423177329e-05"/>
        </inertial>
    </link>
    <!-- Adapter to Foot joint -->
    <joint name="LH_ADAPTER_TO_FOOT" type="fixed" dont_collapse="true">
        <parent link="LH_ADAPTER"/>
        <child link="RL_foot"/>
        <origin rpy="0.0 -0.0 -0.0" xyz="-0.0 0.0 -0.32125"/>
    </joint>
    <!-- Foot link -->
    <link name="RL_foot">
        <collision>
            <origin xyz="0 0 0.02325"/>
            <geometry>
                <sphere radius="0.031"/>
            </geometry>
        </collision>
        <inertial>
            <origin rpy="0 0 0" xyz="0 0 0.02325"/>
            <mass value="0.05"/>
            <inertia ixx="0.001" ixy="-2.63048e-07" ixz="6.815581e-06" iyy="0.001" iyz="-6.815583e-06" izz="8.319196e-06"/>
        </inertial>
    </link>
    <link name="RR_hip">
        <visual>
            <origin rpy="0 0 -3.14159265359" xyz="0 0 0"/>
            <geometry>
                <mesh filename="../meshes/anymal_hip_l.dae" scale="0.001 0.001     0.001"/>
            </geometry>
        </visual>
        <inertial>
            <origin rpy="0 0 0" xyz="-0.064516258147 0.003787101702 -0.000152184388"/>
            <mass value="1.42462064"/>
            <inertia ixx="0.00243023349564" ixy="-1.53023971e-05" ixz="2.1819095354e-05" iyy="0.00230257239103" iyz="-2.6473021273e-05" izz="0.0019806759227"/>
        </inertial>
    </link>
    <!-- Hip joint -->
    <joint name="RR_hip_joint" type="revolute">
        <parent link="base"/>
        <child link="RR_hip"/>
        <origin xyz="-0.277 -0.116 0.0"/>
        <axis xyz="1 0 0"/>
        <limit command_effort="80" current="10" effort="80" gear_velocity="10" lower="-9.42" upper="9.42" velocity="15"/>
        <dynamics damping="0.0" friction="0.0"/>
    </joint>
    <link name="RR_thigh">
        <visual>
            <origin rpy="0 0 -3.14159265359" xyz="0 0 0"/>
            <geometry>
                <mesh filename="../meshes/anymal_thigh_l.dae" scale="0.001 0.001     0.001"/>
            </geometry>
            <!-- <material name="anymal_material"/>     -->
        </visual>
        <collision>
            <!-- KFE actuator -->
            <origin rpy="1.57079632679 0 0" xyz="0.0 -0.069 -0.25"/>
            <geometry>
                <cylinder length="0.12" radius="0.06"/>
            </geometry>
        </collision>
        <inertial>
            <origin rpy="0 0 0" xyz="0.003897968082 -0.054226618537 -0.214583373795"/>
            <mass value="1.634976467"/>
            <inertia ixx="0.0120367944369" ixy="6.762065206e-05" ixz="-0.000287806340448" iyy="0.0120643637939" iyz="0.00140610131218" izz="0.00249422574881"/>
        </inertial>
    </link>
    <!-- Thigh joint -->
    <joint name="RR_thigh_joint" type="revolute">
        <parent link="RR_hip"/>
        <child link="RR_thigh"/>
        <origin xyz="-0.0635                    -0.041                    0.0"/>
        <axis xyz="0 1 0"/>
        <limit command_effort="80" effort="80" lower="-9.42" upper="9.42" velocity="20"/> 
        <dynamics damping="0.0" friction="0.0"/>  
    </joint>  
    <link name="RR_calf">
        <visual>      
            <origin rpy="0 0 -3.14159265359" xyz="0 0 0"/>      
            <geometry>        
                <mesh filename="../meshes/anymal_shank_l.dae" scale="0.001 0.001     0.001"/>      
            </geometry>      
            <!-- <material name="anymal_material"/>     -->
        </visual>      
        <inertial>      
            <origin rpy="0 0 0" xyz="-0.030816858139 0.004617229294 0.000893125713"/>      
            <mass value="0.207204302"/>      
            <inertia ixx="0.0002104880248" ixy="-5.6750980345e-05" ixz="-1.0127699391e-05" iyy="0.000676270210023" iyz="8.22869024e-07" izz="0.000545032674924"/>    
        </inertial>  
    </link>  
    <!-- Shank joint -->  
    <joint name="RR_calf_joint" type="revolute">
        <parent link="RR_thigh"/>
        <child link="RR_calf"/>
        <origin xyz="-0.0 -0.109 -0.25"/>    
        <axis xyz="0 1 0"/>
        <limit command_effort="80" effort="80" lower="-9.42" upper="9.42" velocity="20"/> 
        <dynamics damping="0.0" friction="0.0"/>  
    </joint>  
    <!-- Shank to Adapter joint -->  
    <joint name="RR_calf_TO_ADAPTER" type="fixed">
        <parent link="RR_calf"/>
        <child link="RH_ADAPTER"/>    
        <origin rpy="-0.0 -0.0 0.0" xyz="-0.1 0.02 0.0"/>  
    </joint>  
    <!-- Adapter link -->  
    <link name="RH_ADAPTER">    
        <visual>      
            <origin rpy="0 0 -3.14159265359" xyz="0 0 0.032"/>      
            <geometry>        
                <mesh filename="../meshes/anymal_foot.dae" scale="0.001 0.001     0.001"/>      
            </geometry>      
            <!-- <material name="anymal_material"/>     -->
        </visual>    
        <collision>      
            <origin rpy="0 0 0" xyz="0 0 -0.160625"/>      
            <geometry>        
                <cylinder length="0.25" radius="0.015"/>      
            </geometry>      
            <!-- <material name="anymal_material"/>     -->
        </collision>    
        <inertial>      
            <origin rpy="0 0 0" xyz="-8.66e-10 -1.472e-09 -0.244345749188"/>      
            <mass value="0.140170767"/>      
            <inertia ixx="0.00159938741862" ixy="-9.32e-13" ixz="1.039e-11" iyy="0.00159938741932" iyz="1.7563e-11" izz="5.4423177329e-05"/>    
        </inertial>  
    </link>  
    <!-- Adapter to Foot joint -->  
    <joint name="RH_ADAPTER_TO_FOOT" type="fixed" dont_collapse="true">    
        <parent link="RH_ADAPTER"/>    
        <child link="RR_foot"/>
        <origin rpy="-0.0 -0.0 0.0" xyz="-0.0 -0.0 -0.32125"/>  
    </joint>  
    <!-- Foot link -->  
    <link name="RR_foot">
        <collision>      
            <origin xyz="0 0 0.02325"/>      
            <geometry>        
                <sphere radius="0.031"/>      
            </geometry>    
        </collision>  
        <inertial>
            <origin rpy="0 0 0" xyz="0 0 0.02325"/>
            <mass value="0.05"/>
            <inertia ixx="0.001" ixy="-2.63048e-07" ixz="6.815581e-06" iyy="0.001" iyz="-6.815583e-06" izz="8.319196e-06"/>
        </inertial> 
    </link>  
</robot>

