<?xml version="1.0" ?>
<robot name="mini_cheetah_new_description" xmlns:xacro="http://www.ros.org/wiki/xacro">
  <material name="black">
    <color rgba="0.0 0.0 0.0 1.0"/>
  </material>
  <material name="blue">
    <color rgba="0.0 0.0 0.8 1.0"/>
  </material>
  <material name="green">
    <color rgba="0.0 0.8 0.0 1.0"/>
  </material>
  <material name="grey">
    <color rgba="0.2 0.2 0.2 1.0"/>
  </material>
  <material name="silver">
    <color rgba="0.913725490196 0.913725490196 0.847058823529 1.0"/>
  </material>
  <material name="orange">
    <color rgba="1.0 0.423529411765 0.0392156862745 1.0"/>
  </material>
  <material name="brown">
    <color rgba="0.870588235294 0.811764705882 0.764705882353 1.0"/>
  </material>
  <material name="red">
    <color rgba="0.8 0.0 0.0 1.0"/>
  </material>
  <material name="white">
    <color rgba="1.0 1.0 1.0 1.0"/>
  </material>
  <link name="base">
    <visual>
      <origin rpy="0 0 0" xyz="0 0 0"/>
      <geometry>
        <box size="0.001 0.001 0.001"/>
      </geometry>
    </visual>
  </link>
  <joint name="floating_base" type="fixed">
    <origin rpy="0 0 0" xyz="0 0 0"/>
    <parent link="base"/>
    <child link="trunk"/>
  </joint>
  <link name="trunk">
    <visual>
      <geometry>
        <mesh filename="../meshes/mini_body.dae"/>
      </geometry>
      <origin rpy="0.0 0.0 0.0" xyz="0.0 0.0 0.0"/>
    </visual>
    <collision>
        <origin rpy="0 0 0" xyz="0 0 0"/>
        <geometry>
            <box size="0.2762 0.1435 0.074"/>
        </geometry>
    </collision>
    <inertial>
        <mass value="3.3"/>
        <origin xyz="0.0 0.0 0.0"/>
        <inertia ixx="0.011253" ixy="0" ixz="0" iyy="0.036203" iyz="0" izz="0.042673"/>
    </inertial>
  </link>
  
  <joint name="FR_hip_joint" type="revolute">
    <origin rpy="0 0 0" xyz="0.19 -0.049 0.0"/>
    <parent link="trunk"/>
    <child link="FR_hip"/>
    <axis xyz="1 0 0"/>
    <dynamics damping="0.0" friction="0.0"/>
    <limit effort="23.7" lower="-6.28" upper="6.28" velocity="30.1"/>
  </joint>
  
  <link name="FR_hip">
    <visual>
      <geometry>
        <mesh filename="../meshes/mini_abad.dae"/>
      </geometry>
      <origin rpy="3.141592 0.0 1.5708" xyz="-0.055 0.0 0.0"/>
    </visual>
    <collision>
        <origin rpy="1.57079632679 0 0" xyz="0 -0.02 0"/>
        <geometry>
            <cylinder length="0.01" radius="0.046"/>
        </geometry>
    </collision>
    <inertial>
        <mass value="0.54"/>
        <origin xyz="0.0 0.036 0."/>
        <inertia ixx="0.000381" ixy="0.000058" ixz="0.00000045"
            iyy="0.000560" iyz="0.00000095" izz="0.000444"/>
    </inertial>
  </link>


  <joint name="FR_hip_fixed" type="fixed">
    <origin rpy="0 0 0" xyz="0 -0.08 0"/>
    <parent link="FR_hip"/>
    <child link="FR_thigh_shoulder"/>
  </joint>

  <link name="FR_thigh_shoulder">
    <collision>
      <origin rpy="1.57079632679 0 0" xyz="0 0 0"/>
      <geometry>
        <cylinder length="0.032" radius="0.041"/>
      </geometry>
    </collision>
  </link>

  <joint name="FR_thigh_joint" type="revolute">
    <origin rpy="0.0 0.0 0.0" xyz="0.0 -0.062 0.00"/>
    <parent link="FR_hip"/>
    <child link="FR_thigh"/>
    <axis xyz="0 1 0"/>
    <dynamics damping="0.0" friction="0.0"/>
    <limit effort="23.7" lower="-6.28" upper="6.28" velocity="30.1"/>
  </joint>

  <link name="FR_thigh">
    <visual>
      <geometry>
        <mesh filename="../meshes/mini_upper_link.dae"/>
      </geometry>
      <origin rpy="0 -1.5708 0" xyz="0.0 0.0 0.0"/>
    </visual>
    <collision>
      <origin rpy="0 1.57079632679 0" xyz="0 0 -0.1065"/>
      <geometry>
        <box size="0.213 0.0245 0.034"/>
      </geometry>
    </collision>
    <inertial>
        <mass value="0.634"/>
        <origin xyz="0.0 0.016 -0.02"/>
        <inertia ixx="0.001983" ixy="0.000245" ixz="0.000013" iyy="0.002103" iyz="0.0000015" izz="0.000408"/>
    </inertial>
  </link>


  <joint name="FR_calf_joint" type="revolute">
    <origin rpy="0 0 0" xyz="0 0 -0.209"/>
    <parent link="FR_thigh"/>
    <child link="FR_calf"/>
    <axis xyz="0 1 0"/>
    <dynamics damping="0.0" friction="0.0"/>
    <limit effort="23.7" lower="-6.28" upper="6.28" velocity="30.1"/>
  </joint>

  <link name="FR_calf">
    <visual>
      <geometry>
        <mesh filename="../meshes/mini_lower_link.dae"/>
      </geometry>
      <origin rpy="0.0 3.141592 0" xyz="0.0 0.0 0.0"/>
    </visual>
    <collision>
      <origin rpy="0 1.57079632679 0" xyz="0 0 -0.0665"/>
      <geometry>
        <box size="0.173 0.016 0.016"/>
      </geometry>
    </collision>
    <inertial>
        <mass value="0.064"/>
        <origin xyz="0.0 0.0 -0.209"/>
        <inertia ixx="0.000245" ixy="0" ixz="0.0" iyy="0.000248" iyz="0" izz="0.000006"/>
    </inertial>
  </link>


  <joint name="FR_foot_fixed" type="fixed" dont_collapse="true">
    <origin rpy="0 0 0" xyz="0 0 -0.18"/>
    <parent link="FR_calf"/>
    <child link="FR_foot"/>
  </joint>

  <link name="FR_foot">
    <visual>
      <origin rpy="0 0 0" xyz="0 0 0"/>
      <geometry>
        <sphere radius="0.015"/>
      </geometry>
    </visual>
    <collision>
      <origin rpy="0 0 0" xyz="0 0 0"/>
      <geometry>
        <sphere radius="0.015"/>
      </geometry>
    </collision>
    <inertial>
      <mass value="0.15"/>
      <inertia ixx="0.000025" ixy="0" ixz="0" iyy="0.000025" iyz="0" izz="0.000025"/>
    </inertial>
  </link>

  <joint name="FL_hip_joint" type="revolute">
    <origin rpy="0 0 0" xyz="0.1881 0.04675 0"/>
    <parent link="trunk"/>
    <child link="FL_hip"/>
    <axis xyz="1 0 0"/>
    <dynamics damping="0.0" friction="0.0"/>
    <limit effort="23.7" lower="-6.28" upper="6.28" velocity="30.1"/>
  </joint>

  <link name="FL_hip">
    <visual>
      <geometry>
        <mesh filename="../meshes/mini_abad.dae"/>
      </geometry>
      <origin rpy="0. 0. -1.5708" xyz="-0.055 0.0 0.0"/>
    </visual>
    <collision>
      <origin rpy="1.57079632679 0 0" xyz="0 0.02 0"/>
      <geometry>
        <cylinder length="0.04" radius="0.046"/>
      </geometry>
    </collision>
    <inertial>
        <mass value="0.54"/>
        <origin xyz="0.0 0.036 0."/>
        <inertia ixx="0.000381" ixy="0.000058" ixz="0.00000045" iyy="0.000560" iyz="0.00000095" izz="0.000444"/>
    </inertial>
  </link>


  <joint name="FL_hip_fixed" type="fixed">
    <origin rpy="0 0 0" xyz="0 0.08 0"/>
    <parent link="FL_hip"/>
    <child link="FL_thigh_shoulder"/>
  </joint>
  <link name="FL_thigh_shoulder">
    <collision>
      <origin rpy="1.57079632679 0 0" xyz="0 0 0"/>
      <geometry>
        <cylinder length="0.032" radius="0.041"/>
      </geometry>
    </collision>
  </link>
  <joint name="FL_thigh_joint" type="revolute">
    <origin rpy="0 0 0" xyz="0 0.08 0"/>
    <parent link="FL_hip"/>
    <child link="FL_thigh"/>
    <axis xyz="0 1 0"/>
    <dynamics damping="0.0" friction="0.0"/>
    <limit effort="23.7" lower="-6.28" upper="6.28" velocity="30.1"/>
  </joint>
  <link name="FL_thigh">
    <visual>
      <geometry>
        <mesh filename="../meshes/mini_upper_link.dae"/>
      </geometry>
      <origin rpy="0 -1.5708 0" xyz="0.0 0.0 0.0"/>
    </visual>
    <collision>
      <origin rpy="0 1.57079632679 0" xyz="0 0 -0.1065"/>
      <geometry>
        <box size="0.213 0.0245 0.034"/>
      </geometry>
    </collision>
   <inertial>
        <mass value="0.634"/>
        <origin xyz="0.0 0.016 -0.02"/>
        <inertia ixx="0.001983" ixy="0.000245" ixz="0.000013" iyy="0.002103" iyz="0.0000015" izz="0.000408"/>
    </inertial>
  </link>

  <joint name="FL_calf_joint" type="revolute">
    <origin rpy="0 0 0" xyz="0 0 -0.209"/>
    <parent link="FL_thigh"/>
    <child link="FL_calf"/>
    <axis xyz="0 1 0"/>
    <dynamics damping="0.0" friction="0.0"/>
    <limit effort="23.7" lower="-6.28" upper="6.28" velocity="30.1"/>
  </joint>

  <link name="FL_calf">
    <visual>
      <geometry>
        <mesh filename="../meshes/mini_lower_link.dae"/>
      </geometry>
      <origin rpy="0.0 3.141592 0" xyz="0.0 0.0 0.0"/>
    </visual>
    <collision>
      <origin rpy="0 1.57079632679 0" xyz="0 0 -0.0865"/>
      <geometry>
        <box size="0.173 0.016 0.016"/>
      </geometry>
    </collision>
    <inertial>
        <mass value="0.064"/>
        <origin xyz="0.0 0.0 -0.209"/>
        <inertia ixx="0.000245" ixy="0" ixz="0.0" iyy="0.000248" iyz="0" izz="0.000006"/>
    </inertial>
  </link>

  <joint name="FL_foot_fixed" type="fixed" dont_collapse="true">
    <origin rpy="0 0 0" xyz="0 0 -0.18"/>
    <parent link="FL_calf"/>
    <child link="FL_foot"/>
  </joint>
  <link name="FL_foot">
   <visual>
      <origin rpy="0 0 0" xyz="0 0 0"/>
      <geometry>
        <sphere radius="0.015"/>
      </geometry>
    </visual>
    <collision>
      <origin rpy="0 0 0" xyz="0 0 0"/>
      <geometry>
        <sphere radius="0.015"/>
      </geometry>
    </collision>
    <inertial>
      <mass value="0.15"/>
      <inertia ixx="0.000025" ixy="0" ixz="0" iyy="0.000025" iyz="0" izz="0.000025"/>
    </inertial>
  </link>


  <joint name="RR_hip_joint" type="revolute">
    <origin rpy="0 0 0" xyz="-0.19 -0.049 0.0"/>
    <parent link="trunk"/>
    <child link="RR_hip"/>
    <axis xyz="1 0 0"/>
    <dynamics damping="0.0" friction="0.0"/>
    <limit effort="23.7" lower="-6.28" upper="6.28" velocity="30.1"/>
  </joint>

  <link name="RR_hip">
    <visual>
      <geometry>
        <mesh filename="../meshes/mini_abad.dae"/>
      </geometry>
      <origin rpy="0.0 0.0 1.5708" xyz="0.055 0.0 0.0"/>
    </visual>
    <collision>
      <origin rpy="1.57079632679 0 0" xyz="0 -0.02 0"/>
      <geometry>
        <cylinder length="0.01" radius="0.046"/>
      </geometry>
    </collision>
    <inertial>
      <origin rpy="0 0 0" xyz="0.0 0.036 0."/>
      <mass value="0.54"/>
      <inertia ixx="0.000381" ixy="0.000058" ixz="0.00000045" iyy="0.000560" iyz="0.00000095" izz="0.000444"/>    </inertial>
  </link>


  <joint name="RR_hip_fixed" type="fixed">
    <origin rpy="0 0 0" xyz="0 -0.08 0"/>
    <parent link="RR_hip"/>
    <child link="RR_thigh_shoulder"/>
  </joint>

  <link name="RR_thigh_shoulder">
    <collision>
      <origin rpy="1.57079632679 0 0" xyz="0 0 0"/>
      <geometry>
        <cylinder length="0.032" radius="0.041"/>
      </geometry>
    </collision>
  </link>
  <joint name="RR_thigh_joint" type="revolute">
    <origin rpy="0 0 0" xyz="0 -0.062 0"/>
    <parent link="RR_hip"/>
    <child link="RR_thigh"/>
    <axis xyz="0 1 0"/>
    <dynamics damping="0.0" friction="0.0"/>
    <limit effort="23.7" lower="-6.28" upper="6.28" velocity="30.1"/>
  </joint>
  <link name="RR_thigh">
    <visual>
      <geometry>
        <mesh filename="../meshes/mini_upper_link.dae"/>
      </geometry>
      <origin rpy="0 -1.5708 0" xyz="0.0 0.0 0.0"/>
    </visual>
    <collision>
      <origin rpy="0 1.57079632679 0" xyz="0 0 -0.1065"/>
      <geometry>
        <box size="0.213 0.0245 0.034"/>
      </geometry>
    </collision>
    <inertial>
        <mass value="0.634"/>
        <origin xyz="0.0 0.016 -0.02"/>
        <inertia ixx="0.001983" ixy="0.000245" ixz="0.000013" iyy="0.002103" iyz="0.0000015" izz="0.000408"/>
    </inertial>
  </link>


  <joint name="RR_calf_joint" type="revolute">
    <origin rpy="0 0 0" xyz="0 0 -0.209"/>
    <parent link="RR_thigh"/>
    <child link="RR_calf"/>
    <axis xyz="0 1 0"/>
    <dynamics damping="0.0" friction="0.0"/>
    <limit effort="23.7" lower="-6.28" upper="6.28" velocity="30.1"/>
  </joint>

  <link name="RR_calf">
    <visual>
      <geometry>
        <mesh filename="../meshes/mini_lower_link.dae"/>
      </geometry>
      <origin rpy="0.0 3.141592 0" xyz="0.0 0.0 0.0"/>
    </visual>
    <collision>
      <origin rpy="0 1.57079632679 0" xyz="0 0 -0.0865"/>
      <geometry>
        <box size="0.173 0.016 0.016"/>
      </geometry>
    </collision>
    <inertial>
        <mass value="0.064"/>
        <origin xyz="0.0 0.0 -0.209"/>
        <inertia ixx="0.000245" ixy="0" ixz="0.0" iyy="0.000248" iyz="0" izz="0.000006"/>
    </inertial>
  </link>


  <joint name="RR_foot_fixed" type="fixed" dont_collapse="true">
    <origin rpy="0 0 0" xyz="0 0 -0.18"/>
    <parent link="RR_calf"/>
    <child link="RR_foot"/>
  </joint>

  <link name="RR_foot">
   <visual>
      <origin rpy="0 0 0" xyz="0 0 0"/>
      <geometry>
        <sphere radius="0.015"/>
      </geometry>
    </visual>
    <collision>
      <origin rpy="0 0 0" xyz="0 0 0"/>
      <geometry>
        <sphere radius="0.015"/>
      </geometry>
    </collision>
    <inertial>
      <mass value="0.15"/>
      <inertia ixx="0.000025" ixy="0" ixz="0" iyy="0.000025" iyz="0" izz="0.000025"/>
    </inertial>
  </link>

  <joint name="RL_hip_joint" type="revolute">
    <origin rpy="0 0 0" xyz="-0.19 0.049 0.0"/>
    <parent link="trunk"/>
    <child link="RL_hip"/>
    <axis xyz="1 0 0"/>
    <dynamics damping="0.0" friction="0.0"/>
    <limit effort="23.7" lower="-6.28" upper="6.28" velocity="30.1"/>
  </joint>
  <link name="RL_hip">
    <visual>
      <geometry>
        <mesh filename="../meshes/mini_abad.dae"/>
      </geometry>
      <origin rpy="3.141592 0.0 -1.5708" xyz="0.055 0.0 0.0"/>
    </visual>
    <collision>
      <origin rpy="1.57079632679 0 0" xyz="0 0.02 0"/>
      <geometry>
            <cylinder length="0.01" radius="0.046"/>
      </geometry>
    </collision>
    <inertial>
        <mass value="0.54"/>
        <origin xyz="0.0 0.036 0."/>
        <inertia ixx="0.000381" ixy="0.000058" ixz="0.00000045" iyy="0.000560" iyz="0.00000095" izz="0.000444"/>
    </inertial>
  </link>

  <joint name="RL_hip_fixed" type="fixed">
    <origin rpy="0 0 0" xyz="0 0.08 0"/>
    <parent link="RL_hip"/>
    <child link="RL_thigh_shoulder"/>
  </joint>
  <link name="RL_thigh_shoulder">
    <collision>
      <origin rpy="1.57079632679 0 0" xyz="0 0 0"/>
      <geometry>
        <cylinder length="0.032" radius="0.041"/>
      </geometry>
    </collision>
  </link>
  <joint name="RL_thigh_joint" type="revolute">
    <origin rpy="0 0 0" xyz="0 0.062 0"/>
    <parent link="RL_hip"/>
    <child link="RL_thigh"/>
    <axis xyz="0 1 0"/>
    <dynamics damping="0.0" friction="0.0"/>
    <limit effort="23.7" lower="-6.28" upper="6.28" velocity="30.1"/>
  </joint>

  <link name="RL_thigh">
    <visual>
      <geometry>
        <mesh filename="../meshes/mini_upper_link.dae"/>
      </geometry>
      <origin rpy="0 -1.5708 0" xyz="0.0 0.0 0.0"/>
    </visual>
    <collision>
      <origin rpy="0 1.57079632679 0" xyz="0 0 -0.1065"/>
      <geometry>
        <box size="0.213 0.0245 0.034"/>
      </geometry>
    </collision>
    <inertial>
        <mass value="0.634"/>
        <origin xyz="0.0 0.016 -0.02"/>
        <inertia ixx="0.001983" ixy="0.000245" ixz="0.000013" iyy="0.002103" iyz="0.0000015" izz="0.000408"/>
    </inertial>
  </link>


  <joint name="RL_calf_joint" type="revolute">
    <origin rpy="0 0 0" xyz="0 0 -0.209"/>
    <parent link="RL_thigh"/>
    <child link="RL_calf"/>
    <axis xyz="0 1 0"/>
    <dynamics damping="0.0" friction="0.0"/>
    <limit effort="23.7" lower="-6.28" upper="6.28" velocity="30.1"/>
  </joint>

  <link name="RL_calf">
    <visual>
      <geometry>
        <mesh filename="../meshes/mini_lower_link.dae"/>
      </geometry>
      <origin rpy="0.0 3.141592 0" xyz="0.0 0.0 0.0"/>
    </visual>
    <collision>
      <origin rpy="0 1.57079632679 0" xyz="0 0 -0.0665"/>
      <geometry>
        <box size="0.173 0.016 0.016"/>
      </geometry>
    </collision>
    <inertial>
        <mass value="0.064"/>
        <origin xyz="0.0 0.0 -0.209"/>
        <inertia ixx="0.000245" ixy="0" ixz="0.0" iyy="0.000248" iyz="0" izz="0.000006"/>
    </inertial>
  </link>

  <joint name="RL_foot_fixed" type="fixed" dont_collapse="true">
    <origin rpy="0 0 0" xyz="0 0 -0.18"/>
    <parent link="RL_calf"/>
    <child link="RL_foot"/>
  </joint>
  <link name="RL_foot">
    <visual>
      <origin rpy="0 0 0" xyz="0 0 0"/>
      <geometry>
        <sphere radius="0.015"/>
      </geometry>
    </visual>
    <collision>
      <origin rpy="0 0 0" xyz="0 0 0.045"/>
      <geometry>
        <sphere radius="0.015"/>
      </geometry>
    </collision>
    <inertial>
      <mass value="0.15"/>
      <inertia ixx="0.000025" ixy="0" ixz="0" iyy="0.000025" iyz="0" izz="0.000025"/>
    </inertial>
  </link>
</robot>

