<?xml version="1.0" encoding="utf-8"?>
<!-- =================================================================================== -->
<!-- |    This document was autogenerated by xacro from spotmicroai.urdf.xacro         | -->
<!-- |    EDITING THIS FILE BY HAND IS NOT RECOMMENDED                                 | -->
<!-- =================================================================================== -->
<robot name="SpotMicroAI">
  <material name="yellow">
    <color rgba="0.92 0.83 0.0 1"/>
  </material>
  <material name="black">
    <color rgba="0.1 0.1 0.1 1"/>
  </material>
  <material name="grey">
    <color rgba="0.6 0.6 0.6 1"/>
  </material>
  <material name="blue">
    <color rgba="0.0 0.0 0.8 1.0"/>
  </material>
  <material name="green">
    <color rgba="0.0 0.8 0.0 1.0"/>
  </material>
  <!-- Robot Body -->


  <link name="base">
    <visual>
      <origin rpy="0 0 0" xyz="0 0 0"/>
      <geometry>
        <box size="0.001 0.001 0.001"/>
      </geometry>
    </visual>
  </link>

  <joint name="floating_base" type="fixed">
    <origin rpy="0 0 0" xyz="0 0 0"/>
    <parent link="base"/>
    <child link="trunk"/>
  </joint>

  <link name="trunk">
  <visual>
      <geometry>
        <mesh filename="../meshes/body.dae"/>
      </geometry>
    </visual>
    <collision>
      <geometry>
        <mesh filename="../meshes/body.dae"/>
      </geometry>
    </collision>
    <inertial>
      <mass value="16.0"/>
      <inertia ixx="0.0168352186" ixy="0.0004636141" ixz="0.0002367952" iyy="0.0656071082" iyz="3.6671e-05" izz="0.0742720659"/>
    </inertial>
  </link>


  <link name="FL_hip">
   <visual>
      <geometry>
        <mesh filename="../meshes/front_right_hip.dae"/>
      </geometry>
    </visual>
    <collision>
      <geometry>
        <mesh filename="../meshes/front_right_hip.dae"/>
      </geometry>
    </collision>
    <inertial>
      <mass value="2.0"/>
      <inertia ixx="0.0168352186" ixy="0.0004636141" ixz="0.0002367952" iyy="0.0656071082" iyz="3.6671e-05" izz="0.0742720659"/>
    </inertial>
  </link>

  <link name="FL_thigh_cover">
    <visual>
      <geometry>
            <mesh filename="../meshes/larm_cover.dae" scale="0.001 0.001 0.001"/>
      </geometry>
      <origin rpy="0 0 3.1416" xyz="0.134 -0.04 -0.0095"/>
      <material name="yellow"/>
    </visual>
          <inertial>
      <mass value="0"/>
      <inertia ixx="0" ixy="0" ixz="0" iyy="0" iyz="0" izz="0"/>
    </inertial>
  </link>

  <link name="FL_thigh">
    <visual>
      <geometry>
            <mesh filename="../meshes/larm.dae" scale="0.001 0.001 0.001"/>
      </geometry>
      <origin rpy="0 0 3.1416" xyz="0.134 -0.04 -0.0095"/>
      <material name="black"/>
    </visual>
    <collision>
      <origin rpy="0.0 0.0 0.0" xyz="0.0 0.0 -0.050"/>
      <geometry>
        <box size="0.028 0.036 0.109"/>
      </geometry>
    </collision>
    <inertial>
      <mass value="0.15"/>
      <inertia ixx="0.005851561134" ixy="1.783284e-06" ixz="0.000328291374" iyy="0.005596155105" iyz="2.1430713e-05" izz="0.00107157026"/>
    </inertial>
  </link>

  <link name="FL_calf">
    <visual>
      <geometry>
         <mesh filename="../meshes/lfoot.dae" scale="0.001 0.001 0.001"/>
      </geometry>
      <origin rpy="0 0 3.1416 " xyz="0.1195 -0.04 0.099"/>
      <material name="black"/>
    </visual>
    <collision>
      <geometry>
        <box size="0.026 0.020 0.13"/>
      </geometry>
      <origin rpy="0.0 0.0 0.0" xyz="0.0 0.0 -0.050"/>
    </collision>
    <inertial>
      <mass value="0.1"/>
      <inertia ixx="0.002939186297" ixy="1.440899e-06" ixz="-0.00010535955" iyy="0.00295576935" iyz="-2.4397752e-05" izz="3.0273372e-05"/>
    </inertial>
  </link>

  <link name="FL_foot">
    <visual>
      <geometry>
            <mesh filename="../meshes/foot.dae" scale="0.001 0.001 0.001"/>
      </geometry>
      <origin rpy="0 0.40010 0" xyz="0 -0.01 0.015"/>
      <material name="grey"/>
    </visual>
    <collision>
      <geometry>
        <sphere radius="0.02"/>
      </geometry>
      <origin rpy="0 0 0" xyz="0 0 0"/>
    </collision>
    <inertial>
      <mass value="0.05"/>
      <inertia ixx="9.6e-06" ixy="0.0" ixz="0.0" iyy="9.6e-06" iyz="0.0" izz="9.6e-06"/>
    </inertial>
  </link>

  <joint name="FL_hip_joint" type="revolute">
    <parent link="trunk"/>
    <child link="FL_hip"/>
    <axis xyz="1 0 0"/>
    <origin rpy="0 0 0" xyz="0.093 0.0395 0"/>
    <limit effort="23.7" lower="-1.0471975512" upper="1.0471975512" velocity="30.1"/>
    <dynamics damping="0.0" friction="0.0"/>
  </joint>

  <joint name="FL_thigh_joint" type="revolute">
    <parent link="FL_hip"/>
    <child link="FL_thigh"/>
    <axis xyz="0 1 0"/>
    <origin rpy="0 0 0" xyz="0 0.055 0"/>
     <limit effort="23.7" lower="-0.663225115758" upper="2.96705972839" velocity="30.1"/>
    <dynamics damping="0.0" friction="0.0"/>
  </joint>

  <joint name="front_left_leg_cover_joint" type="fixed">
    <parent link="FL_thigh"/>
    <child link="FL_thigh_cover"/>
    <origin xyz="0 0 0"/>
  </joint>

  <joint name="FL_calf_joint" type="revolute">
    <parent link="FL_thigh"/>
    <child link="FL_calf"/>
    <axis xyz="0 1 0"/>
    <origin rpy="0 0 0" xyz="0.014 0 -0.109"/>
    <limit effort="23.7" lower="-2.72271363311" upper="-0.837758040957" velocity="30.1"/>
    <dynamics damping="0.0" friction="0.0"/>
  </joint>

  <joint name="FL_foot_fixed" type="fixed"  dont_collapse="true">
    <parent link="FL_calf"/>
    <child link="FL_foot"/>
    <origin xyz="0 0 -0.13"/>
  </joint>
  <link name="FR_hip">
    <visual>
      <geometry>
            <mesh filename="../meshes/rshoulder.dae" scale="0.001 0.001 0.001"/>
      </geometry>
      <origin rpy="0 0 3.1416" xyz="0.135 0.0938 -0.0205"/>
      <material name="black"/>
    </visual>
    <collision>
      <geometry>
        <box size="0.044 0.038 0.07"/>
      </geometry>
      <origin rpy="0 0 0" xyz="0 0 0"/>
    </collision>
    <inertial>
      <mass value="0.10"/>
      <inertia ixx="0.000374268192" ixy="-3.6844422e-05" ixz="-9.86754e-07" iyy="0.000635923669" iyz="1.172894e-06" izz="0.000457647394"/>
    </inertial>
  </link>

  <link name="FR_thigh_cover">
    <visual>
      <geometry>
            <mesh filename="../meshes/rarm_cover.dae" scale="0.001 0.001 0.001"/>
      </geometry>
      <origin rpy="0 0 3.1416" xyz="0.134 0.149 -0.0095"/>
      <material name="yellow"/>
    </visual>
          <inertial>
      <mass value="0"/>
      <inertia ixx="0" ixy="0" ixz="0" iyy="0" iyz="0" izz="0"/>
    </inertial>
  </link>

  <link name="FR_thigh">
    <visual>
      <geometry>
        <mesh filename="../meshes/rarm.dae" scale="0.001 0.001 0.001"/>
      </geometry>
      <origin rpy="0 0 3.1416" xyz="0.134 0.149 -0.0095"/>
      <material name="black"/>
    </visual>
    <collision>
      <origin rpy="0.0 0.0 0.0" xyz="0.0 0.0 -0.050"/>
      <geometry>
        <box size="0.028 0.036 0.109"/>
      </geometry>
    </collision>
    <inertial>
      <mass value="0.15"/>
      <inertia ixx="0.005851561134" ixy="-1.783284e-06" ixz="0.000328291374" iyy="0.005596155105" iyz="-2.1430713e-05" izz="0.00107157026"/>
    </inertial>
  </link>

  <link name="FR_calf">
    <visual>
      <geometry>
            <mesh filename="../meshes/rfoot.dae" scale="0.001 0.001 0.001"/>
      </geometry>
      <origin rpy="0 0 3.1416" xyz="0.1195 0.149 0.099"/>
      <material name="black"/>
    </visual>
    <collision>
      <geometry>
        <box size="0.026 0.020 0.13"/>
      </geometry>
      <origin rpy="0.0 0.0 0.0" xyz="0.0 0.0 -0.050"/>
    </collision>
    <inertial>
      <mass value="0.1"/>
      <inertia ixx="0.002939186297" ixy="1.440899e-06" ixz="-0.00010535955" iyy="0.00295576935" iyz="-2.4397752e-05" izz="3.0273372e-05"/>
    </inertial>
  </link>

  <link name="FR_foot">
    <visual>
      <geometry>
            <mesh filename="../meshes/foot.dae" scale="0.001 0.001 0.001"/>
      </geometry>
      <origin rpy="0 0.40010 0" xyz="0 -0.01 0.015"/>
      <material name="grey"/>
    </visual>
    <collision>
      <geometry>
        <sphere radius="0.02"/>
      </geometry>
      <origin rpy="0 0 0" xyz="0 0 0"/>
    </collision>
    <inertial>
      <mass value="0.05"/>
      <inertia ixx="9.6e-06" ixy="0.0" ixz="0.0" iyy="9.6e-06" iyz="0.0" izz="9.6e-06"/>
    </inertial>
  </link>

  <joint name="FR_hip_joint" type="revolute">
    <parent link="trunk"/>
    <child link="FR_hip"/>
    <axis xyz="1 0 0"/>
    <origin rpy="0 0 0" xyz="0.093 -0.0395 0"/>
    <limit effort="23.7" lower="-1.0471975512" upper="1.0471975512" velocity="30.1"/>
    <dynamics damping="0.0" friction="0.0"/>
  </joint>

  <joint name="FR_thigh_joint" type="revolute">
    <parent link="FR_hip"/>
    <child link="FR_thigh"/>
    <axis xyz="0 1 0"/>
    <origin rpy="0 0 0" xyz="0 -0.055 0"/>
     <limit effort="23.7" lower="-0.663225115758" upper="2.96705972839" velocity="30.1"/>
    <dynamics damping="0.0" friction="0.0"/>
  </joint>

  <joint name="front_right_leg_cover_joint" type="fixed">
    <parent link="FR_thigh"/>
    <child link="FR_thigh_cover"/>
    <origin xyz="0 0 0"/>
  </joint>
  <joint name="FR_calf_joint" type="revolute">
    <parent link="FR_thigh"/>
    <child link="FR_calf"/>
    <axis xyz="0 1 0"/>
    <origin rpy="0 0 0" xyz="0.014 0 -0.109"/>
    <limit effort="23.7" lower="-2.72271363311" upper="-0.837758040957" velocity="30.1"/>
    <dynamics damping="0.0" friction="0.0"/>
  </joint>
  <joint name="FR_foot_fixed" type="fixed"  dont_collapse="true">
    <parent link="FR_calf"/>
    <child link="FR_foot"/>
    <origin xyz="0 0 -0.13"/>
  </joint>

  <link name="RL_hip">
    <visual>
      <geometry>
                <mesh filename="../meshes/lshoulder.dae" scale="0.001 0.001 0.001"/>
      </geometry>
      <origin rpy="0 0 3.1416" xyz="0.135 0.0163 -0.0195"/>
      <material name="black"/>
    </visual>
    <collision>
      <geometry>
        <box size="0.044 0.038 0.07"/>
      </geometry>
      <origin rpy="0 0 0" xyz="0 0 0"/>
    </collision>
    <inertial>
      <mass value="0.10"/>
      <inertia ixx="0.000374268192" ixy="-3.6844422e-05" ixz="9.86754e-07" iyy="0.000635923669" iyz="-1.172894e-06" izz="0.000457647394"/>
    </inertial>
  </link>

  <link name="RL_thigh_cover">
    <visual>
      <geometry>
        <mesh filename="../meshes/larm_cover.dae" scale="0.001 0.001 0.001"/>
      </geometry>
      <origin rpy="0 0 3.1416" xyz="0.134 -0.04 -0.0095"/>
      <material name="yellow"/>
    </visual>
    <inertial>
      <mass value="0"/>
      <inertia ixx="0" ixy="0" ixz="0" iyy="0" iyz="0" izz="0"/>
    </inertial>
  </link>

  <link name="RL_thigh">
    <visual>
      <geometry>
            <mesh filename="../meshes/larm.dae" scale="0.001 0.001 0.001"/>
      </geometry>
      <origin rpy="0 0 3.1416" xyz="0.134 -0.04 -0.0095"/>
      <material name="black"/>
    </visual>
    <collision>
      <origin rpy="0.0 0.0 0.0" xyz="0.0 0.0 -0.050"/>
      <geometry>
        <box size="0.028 0.036 0.109"/>
      </geometry>
    </collision>
    <inertial>
      <mass value="0.15"/>
      <inertia ixx="0.005851561134" ixy="1.783284e-06" ixz="0.000328291374" iyy="0.005596155105" iyz="2.1430713e-05" izz="0.00107157026"/>
    </inertial>
  </link>

  <link name="RL_calf">
    <visual>
      <geometry>
           <mesh filename="../meshes/lfoot.dae" scale="0.001 0.001 0.001"/>
      </geometry>
      <origin rpy="0 0 3.1416 " xyz="0.1195 -0.04 0.099"/>
      <material name="black"/>
    </visual>
    <collision>
      <geometry>
        <box size="0.026 0.020 0.13"/>
      </geometry>
      <origin rpy="0.0 0.0 0.0" xyz="0.0 0.0 -0.050"/>
    </collision>
    <inertial>
      <mass value="0.1"/>
      <inertia ixx="0.002939186297" ixy="1.440899e-06" ixz="-0.00010535955" iyy="0.00295576935" iyz="-2.4397752e-05" izz="3.0273372e-05"/>
    </inertial>
  </link>

  <link name="RL_foot">
    <visual>
      <geometry>
                <mesh filename="../meshes/foot.dae" scale="0.001 0.001 0.001"/>
      </geometry>
      <origin rpy="0 0.40010 0" xyz="0 -0.01 0.015"/>
      <material name="grey"/>
    </visual>
    <collision>
      <geometry>
        <sphere radius="0.02"/>
      </geometry>
      <origin rpy="0 0 0" xyz="0 0 0"/>
    </collision>
    <inertial>
      <mass value="0.05"/>
      <inertia ixx="9.6e-06" ixy="0.0" ixz="0.0" iyy="9.6e-06" iyz="0.0" izz="9.6e-06"/>
    </inertial>
  </link>

  <joint name="RL_hip_joint" type="revolute">
    <parent link="trunk"/>
    <child link="RL_hip"/>
    <axis xyz="1 0 0"/>
    <origin rpy="0 0 0" xyz="-0.093 0.0395 0"/>
    <limit effort="23.7" lower="-1.0471975512" upper="1.0471975512" velocity="30.1"/>
    <dynamics damping="0.0" friction="0.0"/>
  </joint>
  <joint name="RL_thigh_joint" type="revolute">
    <parent link="RL_hip"/>
    <child link="RL_thigh"/>
    <axis xyz="0 1 0"/>
    <origin rpy="0 0 0" xyz="0 0.055 0"/>
     <limit effort="23.7" lower="-0.663225115758" upper="2.96705972839" velocity="30.1"/>
    <dynamics damping="0.0" friction="0.0"/>
  </joint>
  <joint name="rear_left_leg_cover_joint" type="fixed">
    <parent link="RL_thigh"/>
    <child link="RL_thigh_cover"/>
    <origin xyz="0 0 0"/>
  </joint>
  <joint name="RL_calf_joint" type="revolute">
    <parent link="RL_thigh"/>
    <child link="RL_calf"/>
    <axis xyz="0 1 0"/>
    <origin rpy="0 0 0" xyz="0.014 0 -0.109"/>
    <limit effort="23.7" lower="-2.72271363311" upper="-0.837758040957" velocity="30.1"/>
    <dynamics damping="0.0" friction="0.0"/>
  </joint>
  <joint name="RL_foot_fixed" type="fixed" dont_collapse="true">
    <parent link="RL_calf"/>
    <child link="RL_foot"/>
    <origin xyz="0 0 -0.13"/>
  </joint>
  <link name="RR_hip">
    <visual>
      <geometry>
        <mesh filename="../meshes/rshoulder.dae" scale="0.001 0.001 0.001"/>
      </geometry>
      <origin rpy="0 0 3.1416" xyz="0.135 0.0938 -0.0205"/>
      <material name="black"/>
    </visual>
    <collision>
      <geometry>
        <box size="0.044 0.038 0.07"/>
      </geometry>
      <origin rpy="0 0 0" xyz="0 0 0"/>
    </collision>
    <inertial>
      <mass value="0.10"/>
      <inertia ixx="0.000374268192" ixy="3.6844422e-05" ixz="9.86754e-07" iyy="0.000635923669" iyz="1.172894e-06" izz="0.000457647394"/>    </inertial>
  </link>

  <link name="RR_thigh_cover">
    <visual>
      <geometry>
         <mesh filename="../meshes/rarm_cover.dae" scale="0.001 0.001 0.001"/>
      </geometry>
      <origin rpy="0 0 3.1416" xyz="0.134 0.149 -0.0095"/>
      <material name="yellow"/>
    </visual>
          <inertial>
      <mass value="0"/>
      <inertia ixx="0" ixy="0" ixz="0" iyy="0" iyz="0" izz="0"/>
    </inertial>
  </link>

  <link name="RR_thigh">
    <visual>
      <geometry>
            <mesh filename="../meshes/rarm.dae" scale="0.001 0.001 0.001"/>
      </geometry>
      <origin rpy="0 0 3.1416" xyz="0.134 0.149 -0.0095"/>
      <material name="black"/>
    </visual>
    <collision>
      <origin rpy="0.0 0.0 0.0" xyz="0.0 0.0 -0.050"/>
      <geometry>
        <box size="0.028 0.036 0.109"/>
      </geometry>
    </collision>
    <inertial>
      <mass value="0.15"/>
      <inertia ixx="0.005851561134" ixy="-1.783284e-06" ixz="0.000328291374" iyy="0.005596155105" iyz="-2.1430713e-05" izz="0.00107157026"/>
    </inertial>
  </link>

  <link name="RR_calf">
    <visual>
      <geometry>
          <mesh filename="../meshes/rfoot.dae" scale="0.001 0.001 0.001"/>
      </geometry>
      <origin rpy="0 0 3.1416" xyz="0.1195 0.149 0.099"/>
      <material name="black"/>
    </visual>
    <collision>
      <geometry>
        <box size="0.026 0.020 0.13"/>
      </geometry>
      <origin rpy="0.0 0.0 0.0" xyz="0.0 0.0 -0.050"/>
    </collision>
    <inertial>
      <mass value="0.1"/>
      <inertia ixx="0.002939186297" ixy="1.440899e-06" ixz="-0.00010535955" iyy="0.00295576935" iyz="-2.4397752e-05" izz="3.0273372e-05"/>
    </inertial>
  </link>

  <link name="RR_foot">
    <visual>
      <geometry>
            <mesh filename="../meshes/foot.dae" scale="0.001 0.001 0.001"/>
      </geometry>
      <origin rpy="0 0.40010 0" xyz="0 -0.01 0.015"/>
      <material name="grey"/>
    </visual>
    <collision>
      <geometry>
        <sphere radius="0.02"/>
      </geometry>
      <origin rpy="0 0 0" xyz="0 0 0"/>
    </collision>
    <inertial>
      <mass value="0.05"/>
      <inertia ixx="9.6e-06" ixy="0.0" ixz="0.0" iyy="9.6e-06" iyz="0.0" izz="9.6e-06"/>
    </inertial>
  </link>

  <joint name="RR_hip_joint" type="revolute">
    <parent link="trunk"/>
    <child link="RR_hip"/>
    <axis xyz="1 0 0"/>
    <origin rpy="0 0 0" xyz="-0.093 -0.0395 0"/>
    <limit effort="23.7" lower="-1.0471975512" upper="1.0471975512" velocity="30.1"/>
    <dynamics damping="0.0" friction="0.0"/>
  </joint>

  <joint name="RR_thigh_joint" type="revolute">
    <parent link="RR_hip"/>
    <child link="RR_thigh"/>
    <axis xyz="0 1 0"/>
    <origin rpy="0 0 0" xyz="0 -0.055 0"/>
     <limit effort="23.7" lower="-0.663225115758" upper="2.96705972839" velocity="30.1"/>
    <dynamics damping="0.0" friction="0.0"/>
  </joint>
  <joint name="rear_right_leg_cover_joint" type="fixed">
    <parent link="RR_thigh"/>
    <child link="RR_thigh_cover"/>
    <origin xyz="0 0 0"/>
  </joint>
  <joint name="RR_calf_joint" type="revolute">
    <parent link="RR_thigh"/>
    <child link="RR_calf"/>
    <axis xyz="0 1 0"/>
    <origin rpy="0 0 0" xyz="0.014 0 -0.109"/>
    <limit effort="23.7" lower="-2.72271363311" upper="-0.837758040957" velocity="30.1"/>
    <dynamics damping="0.0" friction="0.0"/>
  </joint>

  <joint name="RR_foot_fixed" type="fixed"  dont_collapse="true">
    <parent link="RR_calf"/>
    <child link="RR_foot"/>
    <origin xyz="0 0 -0.13"/>
  </joint>
</robot>

