<?xml version="1.0" encoding="utf-8"?>
<robot name="spot_description">
  <link name="base">
    <visual>
      <origin rpy="0 0 0" xyz="0 0 0"/>
      <geometry>
        <box size="0.001 0.001 0.001"/>
      </geometry>
    </visual>
  </link>
  <joint name="floating_base" type="fixed">
    <origin rpy="0 0 0" xyz="0 0 0"/>
    <parent link="base"/>
    <child link="trunk"/>
  </joint>


  <link name="trunk">
    <visual>
      <geometry>
        <mesh filename="../meshes/body.dae"/>
      </geometry>
    </visual>
    <collision>
      <geometry>
        <mesh filename="../meshes/body.dae"/>
      </geometry>
    </collision>
    <inertial>
      <mass value="16.0"/>
      <inertia ixx="0.0973333333333" ixy="0.0" ixz="0.0" iyy="1.02466666667" iyz="0.0" izz="1.04493333333"/>
    </inertial>
  </link>

  <link name="FR_hip">
    <visual>
      <geometry>
        <mesh filename="../meshes/front_right_hip.dae"/>
      </geometry>
    </visual>
    <collision>
      <geometry>
        <mesh filename="../meshes/front_right_hip.dae"/>
      </geometry>
    </collision>
    <inertial>
      <mass value="2.0"/>
      <inertia ixx="0.0027" ixy="0.0" ixz="0.0" iyy="0.00416666666667" iyz="0.0" izz="0.00416666666667"/>
    </inertial>
  </link>
  <joint name="FR_hip_joint" type="revolute">
    <origin rpy="0 0 0" xyz="0.29785 -0.055 0"/>
    <axis xyz="1 0 0"/>
    <parent link="trunk"/>
    <child link="FR_hip"/>
    <limit effort="100" lower="-0.78539816339744827899" upper="0.78539816339744827899" velocity="1000.00"/>
  </joint>
  <link name="FR_thigh">
    <visual>
      <geometry>
        <mesh filename="../meshes/front_right_upper_leg.dae"/>
      </geometry>
    </visual>
    <collision>
      <geometry>
        <mesh filename="../meshes/front_right_upper_leg.dae"/>
      </geometry>
    </collision>
    <inertial>
      <origin rpy="0 0 0" xyz="0 0 -0.14"/>
      <mass value="1.0"/>
      <inertia ixx="0.0155334166667" ixy="0.0" ixz="0.0" iyy="0.0155334166667" iyz="0.0" izz="0.000962666666667"/>
    </inertial>
  </link>
  <joint name="FR_thigh_joint" type="revolute">
    <origin rpy="0 0 0" xyz="0 -0.110945 0"/>
    <axis xyz="0 1 0"/>
    <parent link="FR_hip"/>
    <child link="FR_thigh"/>
    <limit effort="100" lower="-0.89884456477707963539" upper="2.2951079663725435509" velocity="1000.00"/>
  </joint>
  <link name="FR_calf">
    <visual>
      <geometry>
        <mesh filename="../meshes/front_right_lower_leg.dae"/>
      </geometry>
    </visual>
    <collision>
      <geometry>
        <mesh filename="../meshes/front_right_lower_leg.dae"/>
      </geometry>
    </collision>
    <inertial>
      <origin rpy="0 0 0" xyz="0 0 -0.16"/>
      <mass value="0.5"/>
      <inertia ixx="0.007434375" ixy="0.0" ixz="0.0" iyy="0.00740104166667" iyz="0.0" izz="0.000135416666667"/>
    </inertial>
  </link>
  <joint name="FR_calf_joint" type="revolute">
    <origin rpy="0 0 0" xyz="0.025 0 -0.3205"/>
    <axis xyz="0 1 0"/>
    <parent link="FR_thigh"/>
    <child link="FR_calf"/>
    <limit effort="100" lower="-2.7929" upper="-0.254801" velocity="1000.00"/>
  </joint>
  <link name="FR_foot">
      <inertial>
        <mass value="0.25"/>
      <inertia ixx="0.0001" ixy="0.0" ixz="0.0" iyy="0.00001" iyz="0.0" izz="0.00001"/>
      </inertial>
      <collision>
        <origin rpy="0 0 0" xyz="0 0 0.02"/>
        <geometry>
          <sphere radius="0.023"/>
        </geometry>
      </collision>
  </link>
  <joint name="FR_foot_fixed" type="fixed" dont_collapse="true">
    <parent link="FR_calf"/>
    <child link="FR_foot"/>
    <origin rpy="0 0 0" xyz="0 0 -0.37"/>
  </joint>

  <link name="FL_hip">
    <visual>
      <geometry>
        <mesh filename="../meshes/front_left_hip.dae"/>
      </geometry>
    </visual>
    <collision>
      <geometry>
        <mesh filename="../meshes/front_left_hip.dae"/>
      </geometry>
    </collision>
    <inertial>
      <mass value="2.0"/>
      <inertia ixx="0.0027" ixy="0.0" ixz="0.0" iyy="0.00416666666667" iyz="0.0" izz="0.00416666666667"/>
    </inertial>
  </link>

  <joint name="FL_hip_joint" type="revolute">
    <origin rpy="0 0 0" xyz="0.29785 0.055 0"/>
    <axis xyz="1 0 0"/>
    <parent link="trunk"/>
    <child link="FL_hip"/>
    <limit effort="100" lower="-0.78539816339744827899" upper="0.78539816339744827899" velocity="1000.00"/>
  </joint>
  <link name="FL_thigh">
    <visual>
      <geometry>
        <mesh filename="../meshes/front_left_upper_leg.dae"/>
      </geometry>
    </visual>
    <collision>
      <geometry>
        <mesh filename="../meshes/front_left_upper_leg.dae"/>
      </geometry>
    </collision>
    <inertial>
      <origin rpy="0 0 0" xyz="0 0 -0.14"/>
      <mass value="1.0"/>
      <inertia ixx="0.0155334166667" ixy="0.0" ixz="0.0" iyy="0.0155334166667" iyz="0.0" izz="0.000962666666667"/>
    </inertial>
  </link>
  <joint name="FL_thigh_joint" type="revolute">
    <origin rpy="0 0 0" xyz="0 0.110945 0"/>
    <axis xyz="0 1 0"/>
    <parent link="FL_hip"/>
    <child link="FL_thigh"/>
    <limit effort="100" lower="-0.89884456477707963539" upper="2.2951079663725435509" velocity="1000.00"/>
  </joint>
  <link name="FL_calf">
    <visual>
      <geometry>
        <mesh filename="../meshes/front_left_lower_leg.dae"/>
      </geometry>
    </visual>
    <collision>
      <geometry>
        <mesh filename="../meshes/front_left_lower_leg.dae"/>
      </geometry>
    </collision>
    <inertial>
      <origin rpy="0 0 0" xyz="0 0 -0.16"/>
      <mass value="0.5"/>
      <inertia ixx="0.007434375" ixy="0.0" ixz="0.0" iyy="0.00740104166667" iyz="0.0" izz="0.000135416666667"/>
    </inertial>
  </link>
  <joint name="FL_calf_joint" type="revolute">
    <origin rpy="0 0 0" xyz="0.025 0 -0.3205"/>
    <axis xyz="0 1 0"/>
    <parent link="FL_thigh"/>
    <child link="FL_calf"/>
    <limit effort="100" lower="-2.7929" upper="-0.254801" velocity="1000.00"/>
  </joint>
  <link name="FL_foot">
      <inertial>
        <mass value="0.25"/>
      <inertia ixx="0.0001" ixy="0.0" ixz="0.0" iyy="0.00001" iyz="0.0" izz="0.00001"/>
      </inertial>
      <collision>
        <origin rpy="0 0 0" xyz="0 0 0.02"/>
        <geometry>
          <sphere radius="0.023"/>
        </geometry>
      </collision>
  </link>
  <joint name="FL_foot_fixed" type="fixed" dont_collapse="true">
    <parent link="FL_calf"/>
    <child link="FL_foot"/>
    <origin rpy="0 0 0" xyz="0 0 -0.37"/>
  </joint>

  <link name="RR_hip">
    <visual>
      <geometry>
        <mesh filename="../meshes/rear_right_hip.dae"/>
      </geometry>
    </visual>
    <collision>
      <geometry>
        <mesh filename="../meshes/rear_right_hip.dae"/>
      </geometry>
    </collision>
    <inertial>
      <mass value="2.0"/>
      <inertia ixx="0.0027" ixy="0.0" ixz="0.0" iyy="0.00416666666667" iyz="0.0" izz="0.00416666666667"/>
    </inertial>
  </link>
  <joint name="RR_hip_joint" type="revolute">
    <origin rpy="0 0 0" xyz="-0.29785 -0.055 0"/>
    <axis xyz="1 0 0"/>
    <parent link="trunk"/>
    <child link="RR_hip"/>
    <limit effort="100" lower="-0.78539816339744827899" upper="0.78539816339744827899" velocity="1000.00"/>
  </joint>
  <link name="RR_thigh">
    <visual>
      <geometry>
        <mesh filename="../meshes/rear_right_upper_leg.dae"/>
      </geometry>
    </visual>
    <collision>
      <geometry>
        <mesh filename="../meshes/rear_right_upper_leg.dae"/>
      </geometry>
    </collision>
    <inertial>
      <origin rpy="0 0 0" xyz="0 0 -0.14"/>
      <mass value="1.0"/>
      <inertia ixx="0.0155334166667" ixy="0.0" ixz="0.0" iyy="0.0155334166667" iyz="0.0" izz="0.000962666666667"/>
    </inertial>
  </link>
  <joint name="RR_thigh_joint" type="revolute">
    <origin rpy="0 0 0" xyz="0 -0.110945 0"/>
    <axis xyz="0 1 0"/>
    <parent link="RR_hip"/>
    <child link="RR_thigh"/>
    <limit effort="100" lower="-0.89884456477707963539" upper="2.2951079663725435509" velocity="1000.00"/>
  </joint>
  <link name="RR_calf">
    <visual>
      <geometry>
        <mesh filename="../meshes/rear_right_lower_leg.dae"/>
      </geometry>
    </visual>
    <collision>
      <geometry>
        <mesh filename="../meshes/rear_right_lower_leg.dae"/>
      </geometry>
    </collision>
    <inertial>
      <origin rpy="0 0 0" xyz="0 0 -0.16"/>
      <mass value="0.5"/>
      <inertia ixx="0.007434375" ixy="0.0" ixz="0.0" iyy="0.00740104166667" iyz="0.0" izz="0.000135416666667"/>
    </inertial>
  </link>
  <joint name="RR_calf_joint" type="revolute">
    <origin rpy="0 0 0" xyz="0.025 0 -0.3205"/>
    <axis xyz="0 1 0"/>
    <parent link="RR_thigh"/>
    <child link="RR_calf"/>
    <limit effort="100" lower="-2.7929" upper="-0.254801" velocity="1000.00"/>
  </joint>
  <link name="RR_foot">
      <inertial>
        <mass value="0.25"/>
      <inertia ixx="0.0001" ixy="0.0" ixz="0.0" iyy="0.00001" iyz="0.0" izz="0.00001"/>
      </inertial>
      <collision>
        <origin rpy="0 0 0" xyz="0 0 0.02"/>
        <geometry>
          <sphere radius="0.023"/>
        </geometry>
      </collision>
  </link>
  <joint name="RR_foot_fixed" type="fixed" dont_collapse="true">
    <parent link="RR_calf"/>
    <child link="RR_foot"/>
    <origin rpy="0 0 0" xyz="0 0 -0.37"/>
  </joint>


  <link name="RL_hip">
    <visual>
      <geometry>
        <mesh filename="../meshes/rear_left_hip.dae"/>
      </geometry>
    </visual>
    <collision>
      <geometry>
        <mesh filename="../meshes/rear_left_hip.dae"/>
      </geometry>
    </collision>
    <inertial>
      <mass value="2.0"/>
      <inertia ixx="0.0027" ixy="0.0" ixz="0.0" iyy="0.00416666666667" iyz="0.0" izz="0.00416666666667"/>
    </inertial>
  </link>
  <joint name="RL_hip_joint" type="revolute">
    <origin rpy="0 0 0" xyz="-0.29785 0.055 0"/>
    <axis xyz="1 0 0"/>
    <parent link="trunk"/>
    <child link="RL_hip"/>
    <limit effort="100" lower="-0.78539816339744827899" upper="0.78539816339744827899" velocity="1000.00"/>
  </joint>
  <link name="RL_thigh">
    <visual>
      <geometry>
        <mesh filename="../meshes/rear_left_upper_leg.dae"/>
      </geometry>
    </visual>
    <collision>
      <geometry>
        <mesh filename="../meshes/rear_left_upper_leg.dae"/>
      </geometry>
    </collision>
    <inertial>
      <origin rpy="0 0 0" xyz="0 0 -0.14"/>
      <mass value="1.0"/>
      <inertia ixx="0.0155334166667" ixy="0.0" ixz="0.0" iyy="0.0155334166667" iyz="0.0" izz="0.000962666666667"/>
    </inertial>
  </link>
  <joint name="RL_thigh_joint" type="revolute">
    <origin rpy="0 0 0" xyz="0 0.110945 0"/>
    <axis xyz="0 1 0"/>
    <parent link="RL_hip"/>
    <child link="RL_thigh"/>
    <limit effort="100" lower="-0.89884456477707963539" upper="2.2951079663725435509" velocity="1000.00"/>
  </joint>
  <link name="RL_calf">
    <visual>
      <geometry>
        <mesh filename="../meshes/rear_left_lower_leg.dae"/>
      </geometry>
    </visual>
    <collision>
      <geometry>
        <mesh filename="../meshes/rear_left_lower_leg.dae"/>
      </geometry>
    </collision>
    <inertial>
      <origin rpy="0 0 0" xyz="0 0 -0.16"/>
      <mass value="0.5"/>
      <inertia ixx="0.007434375" ixy="0.0" ixz="0.0" iyy="0.00740104166667" iyz="0.0" izz="0.000135416666667"/>
    </inertial>
  </link>
  <joint name="RL_calf_joint" type="revolute">
    <origin rpy="0 0 0" xyz="0.025 0 -0.3205"/>
    <axis xyz="0 1 0"/>
    <parent link="RL_thigh"/>
    <child link="RL_calf"/>
    <limit effort="100" lower="-2.7929" upper="-0.254801" velocity="1000.00"/>
  </joint>
  <link name="RL_foot">
      <inertial>
        <mass value="0.25"/>
      <inertia ixx="0.0001" ixy="0.0" ixz="0.0" iyy="0.00001" iyz="0.0" izz="0.00001"/>
      </inertial>
      <collision>
        <origin rpy="0 0 0" xyz="0 0 0.02"/>
        <geometry>
          <sphere radius="0.023"/>
        </geometry>
      </collision>
  </link>
  <joint name="RL_foot_fixed" type="fixed" dont_collapse="true">
    <parent link="RL_calf"/>
    <child link="RL_foot"/>
    <origin rpy="0 0 0" xyz="0 0 -0.37"/>
  </joint>

</robot>

